<?xml version="1.0"?>
<robot name="buggy" xmlns:xacro="http://www.ros.org/wiki/xacro">
  <link name="chassis">
    <visual>
      <geometry>
        <box size="0.6 0.3 0.1"/>
      </geometry>
    </visual>

    <inertial>
      <origin xyz="0 0 1" rpy="0 0 0"/>
      <mass value="2"/>
      <inertia
        ixx="1.0" ixy="0.0" ixz="0.0"
        iyy="1.0" iyz="0.0"
        izz="1.0"/>
    </inertial>
  </link>

  <link name="left_wheel">
    <visual>
      <geometry>
        <cylinder radius="0.1" length="0.2"/>
      </geometry>
    </visual>

    <collision>
      <geometry>
        <cylinder radius="0.1" length="0.2"/>
      </geometry>
    </collision>

    <inertial>
      <origin xyz="0 0 1" rpy="0 0 0"/>
      <mass value="2"/>
      <inertia
        ixx="1.0" ixy="0.0" ixz="0.0"
        iyy="1.0" iyz="0.0"
        izz="1.0"/>
    </inertial>
  </link>
      
  <gazebo reference="chassis">
    <turnGravityOff>true</turnGravityOff>
  </gazebo>

  <joint name="left_wheel_hinge" type="revolute">
    <axis xyz="0 0 1"/>
    <limit effort="1000.0" lower="0.0" upper="0.548" velocity="0.5"/>
    <origin rpy="0 0 0" xyz="0.2 0.01 0"/>
    <parent link="chassis"/>
    <child link="left_wheel"/>
  </joint>
</robot>
